Workbook

Sheet Cover
A1: Luckin Coffee Inc. (LKNCY) - IBD Operating Model & DCF
A3: Company | B3: Luckin Coffee Inc. / 瑞幸咖啡
A4: Ticker / exchange | B4: LKNCY / OTC Markets | Wind: LKNCY.OO
A5: Model status | B5: REAL HISTORICAL DATA | PROVISIONAL FORECAST | NOT INVESTMENT ADVICE
A6: As of | B6: 2026-09-06
A7: Currency / units | B7: CNY / RMB mm; valuation output in USD per ADS
A9: Primary source | B9: https://www.sec.gov/Archives/edgar/data/1767582/000110465926035712/lk-20251231x20f.htm
A10: Earlier source | B10: https://www.sec.gov/Archives/edgar/data/1767582/000110465924044514/lk-20231231x20f.htm
A11: SEC company facts | B11: https://data.sec.gov/api/xbrl/companyfacts/CIK0001767582.json
A12: Source ledger | B12: source_ledger.json
A14: Color legend | B14: Blue = hardcode | Black = same-sheet formula | Green = cross-tab formula
A15: Tab directory | B15: Cover | Assumptions | IS | BS | CF | DCF | Sensitivity
A16: Scenario selector | B16: Assumptions!B4 (1=Bear, 2=Base, 3=Bull)
A18: Key outputs
A19: 2025A revenue | B19: =IS!E21 -> 49288.095
A20: 2025A EBIT margin | B20: =IS!E46 -> 0.10292414
A21: 2030E Base revenue | B21: =IS!J21 -> 130928.2
A22: Implied value / ADS | B22: =DCF!B69 -> 46.697081
A23: Upside / (downside) | B23: =DCF!B71 -> 0.34148466
A25: Forecast caveat | B25: 2026E-2030E are editable skill-default scenarios, not management guidance or licensed consensus.

Sheet Assumptions
A1: Luckin Coffee Inc. - Assumptions (RMB mm)
A2: All forecast inputs live here. Selected is formula-driven; statements contain no forecast hardcodes.
A4: Case selector (1=Bear, 2=Base, 3=Bull) | B4: 2 | C4: Selected case | D4: =CHOOSE($B$4,"Bear","Base","Bull") -> Base
A6: Historical context
A7: Metric | B7: Unit | C7: 2022A | D7: 2023A | E7: 2024A | F7: 2025A | G7: Source / note
A8: Revenue | B8: RMB mm | C8: =IS!B21 -> 13292.982 | D8: =IS!C21 -> 24903.166 | E8: =IS!D21 -> 34474.814 | F8: =IS!E21 -> 49288.095 | G8: Official 20-F
A9: EBIT margin | B9: % | C9: =IS!B46 -> 0.086976647 | D9: =IS!C46 -> 0.12128671 | E9: =IS!D46 -> 0.10355586 | F9: =IS!E46 -> 0.10292414 | G9: Derived from 20-F rows
A10: Ending stores | B10: count | C10: =IS!B5+IS!B13 -> 8214 | D10: =IS!C5+IS!C13 -> 16248 | E10: =IS!D5+IS!D13 -> 22340 | F10: =IS!E5+IS!E13 -> 31048 | G10: Official 20-F KPI table
A11: Product revenue / avg self store | B11: RMB mm | C11: =IS!B8 -> 2.0347736 | D11: =IS!C8 -> 2.2945197 | E11: =IS!D8 -> 2.1197925 | F11: =IS!E8 -> 2.1647899 | G11: Model-derived
A12: Partnership revenue / avg partner store | B12: RMB mm | C12: =IS!B16 -> 1.4653913 | D12: =IS!C16 -> 1.5218225 | E12: =IS!D16 -> 1.1586941 | F12: =IS!E16 -> 1.2491181 | G12: Model-derived
A13: CFO margin | B13: % | C13: =CF!B9 -> 0.0014908619 | D13: =CF!C9 -> 0.11646812 | E13: =CF!D9 -> 0.12267715 | F13: =CF!E9 -> 0.1235808 | G13: Derived from 20-F rows
A15: 2021A ending self stores | B15: 4397 | C15: Input used only for 2022 average-store calculation
A16: 2021A ending partnership stores | B16: 1627 | C16: Input used only for 2022 average-store calculation
A18: Scenario forecast drivers
A19: Assumption key | B19: Unit | C19: Forecast period | D19: Bear | E19: Base | F19: Bull | G19: Selected | H19: Status | I19: Provenance | J19: Rationale / source
A20: Self-operated store growth | B20: % | C20: 2026E | D20: 0.18 | E20: 0.25 | F20: 0.3 | G20: =INDEX($D20:$F20,1,$B$4) -> 0.25 | H20: provisional | I20: skill_default | J20: Historical store/revenue productivity trend with explicit downside/upside; provisional, not consensus.
A21: Self-operated store growth | B21: % | C21: 2027E | D21: 0.15 | E21: 0.2 | F21: 0.25 | G21: =INDEX($D21:$F21,1,$B$4) -> 0.2 | H21: provisional | I21: skill_default | J21: Historical store/revenue productivity trend with explicit downside/upside; provisional, not consensus.
A22: Self-operated store growth | B22: % | C22: 2028E | D22: 0.12 | E22: 0.16 | F22: 0.2 | G22: =INDEX($D22:$F22,1,$B$4) -> 0.16 | H22: provisional | I22: skill_default | J22: Historical store/revenue productivity trend with explicit downside/upside; provisional, not consensus.
A23: Self-operated store growth | B23: % | C23: 2029E | D23: 0.1 | E23: 0.12 | F23: 0.16 | G23: =INDEX($D23:$F23,1,$B$4) -> 0.12 | H23: provisional | I23: skill_default | J23: Historical store/revenue productivity trend with explicit downside/upside; provisional, not consensus.
A24: Self-operated store growth | B24: % | C24: 2030E | D24: 0.08 | E24: 0.1 | F24: 0.12 | G24: =INDEX($D24:$F24,1,$B$4) -> 0.1 | H24: provisional | I24: skill_default | J24: Historical store/revenue productivity trend with explicit downside/upside; provisional, not consensus.
A25: Partnership store growth | B25: % | C25: 2026E | D25: 0.18 | E25: 0.25 | F25: 0.32 | G25: =INDEX($D25:$F25,1,$B$4) -> 0.25 | H25: provisional | I25: skill_default | J25: Historical store/revenue productivity trend with explicit downside/upside; provisional, not consensus.
A26: Partnership store growth | B26: % | C26: 2027E | D26: 0.16 | E26: 0.22 | F26: 0.28 | G26: =INDEX($D26:$F26,1,$B$4) -> 0.22 | H26: provisional | I26: skill_default | J26: Historical store/revenue productivity trend with explicit downside/upside; provisional, not consensus.
A27: Partnership store growth | B27: % | C27: 2028E | D27: 0.14 | E27: 0.18 | F27: 0.22 | G27: =INDEX($D27:$F27,1,$B$4) -> 0.18 | H27: provisional | I27: skill_default | J27: Historical store/revenue productivity trend with explicit downside/upside; provisional, not consensus.
A28: Partnership store growth | B28: % | C28: 2029E | D28: 0.12 | E28: 0.15 | F28: 0.18 | G28: =INDEX($D28:$F28,1,$B$4) -> 0.15 | H28: provisional | I28: skill_default | J28: Historical store/revenue productivity trend with explicit downside/upside; provisional, not consensus.
A29: Partnership store growth | B29: % | C29: 2030E | D29: 0.1 | E29: 0.12 | F29: 0.15 | G29: =INDEX($D29:$F29,1,$B$4) -> 0.12 | H29: provisional | I29: skill_default | J29: Historical store/revenue productivity trend with explicit downside/upside; provisional, not consensus.
A30: Product revenue / store growth | B30: % | C30: 2026E | D30: -0.06 | E30: -0.02 | F30: 0.01 | G30: =INDEX($D30:$F30,1,$B$4) -> -0.02 | H30: provisional | I30: skill_default | J30: Historical store/revenue productivity trend with explicit downside/upside; provisional, not consensus.
A31: Product revenue / store growth | B31: % | C31: 2027E | D31: -0.01 | E31: 0.02 | F31: 0.04 | G31: =INDEX($D31:$F31,1,$B$4) -> 0.02 | H31: provisional | I31: skill_default | J31: Historical store/revenue productivity trend with explicit downside/upside; provisional, not consensus.
... A147: Mezzanine equity | B147: RMB mm | C147: All forecast | D147: 1514.66 | E147: 1514.66 | F147: 1514.66 | G147: =INDEX($D147:$F147,1,$B$4) -> 1514.66 | H147: committed | I147: source_lookup | J147: Deducted after enterprise value to reach common equity value.
A149: Sensitivity axes
A150: Axis key | B150: Unit | C150: Position | D150: Value | H150: Status | I150: Provenance | J150: Rationale
A151: wacc_axis | B151: % | C151: 1 | D151: 0.10575 | H151: provisional | I151: skill_default | J151: Center equals Base; outer cells are symmetric stress cases.
A152: wacc_axis | B152: % | C152: 2 | D152: 0.11075 | H152: provisional | I152: skill_default | J152: Center equals Base; outer cells are symmetric stress cases.
A153: wacc_axis | B153: % | C153: 3 | D153: 0.11575 | H153: provisional | I153: skill_default | J153: Center equals Base; outer cells are symmetric stress cases.
A154: wacc_axis | B154: % | C154: 4 | D154: 0.12075 | H154: provisional | I154: skill_default | J154: Center equals Base; outer cells are symmetric stress cases.
A155: wacc_axis | B155: % | C155: 5 | D155: 0.12575 | H155: provisional | I155: skill_default | J155: Center equals Base; outer cells are symmetric stress cases.
A156: terminal_growth_axis | B156: % | C156: 1 | D156: 0.015 | H156: provisional | I156: skill_default | J156: Center equals Base; outer cells are symmetric stress cases.
A157: terminal_growth_axis | B157: % | C157: 2 | D157: 0.02 | H157: provisional | I157: skill_default | J157: Center equals Base; outer cells are symmetric stress cases.
A158: terminal_growth_axis | B158: % | C158: 3 | D158: 0.025 | H158: provisional | I158: skill_default | J158: Center equals Base; outer cells are symmetric stress cases.
A159: terminal_growth_axis | B159: % | C159: 4 | D159: 0.03 | H159: provisional | I159: skill_default | J159: Center equals Base; outer cells are symmetric stress cases.
A160: terminal_growth_axis | B160: % | C160: 5 | D160: 0.035 | H160: provisional | I160: skill_default | J160: Center equals Base; outer cells are symmetric stress cases.
...

Sheet IS
A1: Income Statement & Operating KPIs (RMB mm, except per-store and store data)
A2: Selected case | B2: =Assumptions!$D$4 -> Base
A4: Income Statement / KPI | B4: 2022A | C4: 2023A | D4: 2024A | E4: 2025A | F4: 2026E | G4: 2027E | H4: 2028E | I4: 2029E | J4: 2030E
A5: Ending direct stores | B5: 5652 | C5: 10628 | D5: 14591 | E5: 20234 | F5: =E5*(1+Assumptions!$G$20) -> 25292.5 | G5: =F5*(1+Assumptions!$G$21) -> 30351 | H5: =G5*(1+Assumptions!$G$22) -> 35207.16 | I5: =H5*(1+Assumptions!$G$23) -> 39432.019 | J5: =I5*(1+Assumptions!$G$24) -> 43375.221
A6: Direct-store YoY | B6: unavailable | C6: =C5/B5-1 -> 0.88039632 | D6: =D5/C5-1 -> 0.37288295 | E6: =E5/D5-1 -> 0.38674525 | F6: =F5/E5-1 -> 0.25 | G6: =G5/F5-1 -> 0.2 | H6: =H5/G5-1 -> 0.16 | I6: =I5/H5-1 -> 0.12 | J6: =J5/I5-1 -> 0.1
A7: Average direct stores | B7: =AVERAGE(Assumptions!$B$15,B5) -> 5024.5 | C7: =AVERAGE(B5,C5) -> 8140 | D7: =AVERAGE(C5,D5) -> 12609.5 | E7: =AVERAGE(D5,E5) -> 17412.5 | F7: =AVERAGE(E5,F5) -> 22763.25 | G7: =AVERAGE(F5,G5) -> 27821.75 | H7: =AVERAGE(G5,H5) -> 32779.08 | I7: =AVERAGE(H5,I5) -> 37319.59 | J7: =AVERAGE(I5,J5) -> 41403.62
A8: Product revenue / average self store | B8: =B10/B7 -> 2.0347736 | C8: =C10/C7 -> 2.2945197 | D8: =D10/D7 -> 2.1197925 | E8: =E10/E7 -> 2.1647899 | F8: =E8*(1+Assumptions!$G$30) -> 2.1214942 | G8: =F8*(1+Assumptions!$G$31) -> 2.163924 | H8: =G8*(1+Assumptions!$G$32) -> 2.2288418 | I8: =H8*(1+Assumptions!$G$33) -> 2.295707 | J8: =I8*(1+Assumptions!$G$34) -> 2.3645782
A9: Product revenue / store YoY | B9: unavailable | C9: =C8/B8-1 -> 0.12765354 | D9: =D8/C8-1 -> -0.076149793 | E9: =E8/D8-1 -> 0.02122731 | F9: =F8/E8-1 -> -0.02 | G9: =G8/F8-1 -> 0.02 | H9: =H8/G8-1 -> 0.03 | I9: =I8/H8-1 -> 0.03 | J9: =J8/I8-1 -> 0.03
A10: Product sales revenue | B10: 10223.72 | C10: 18677.39 | D10: 26729.523 | E10: 37694.405 | F10: =F7*F8 -> 48292.102 | G10: =G7*G8 -> 60204.153 | H10: =H7*H8 -> 73059.382 | I10: =I7*I8 -> 85674.843 | J10: =J7*J8 -> 97902.098
A11: Product sales revenue YoY | B11: unavailable | C11: =C10/B10-1 -> 0.8268683 | D11: =D10/C10-1 -> 0.43111661 | E11: =E10/D10-1 -> 0.41021615 | F11: =F10/E10-1 -> 0.28114774 | G11: =G10/F10-1 -> 0.24666667 | H11: =H10/G10-1 -> 0.21352727 | I11: =I10/H10-1 -> 0.17267407 | J11: =J10/I10-1 -> 0.14271698
A13: Ending partnership stores | B13: 2562 | C13: 5620 | D13: 7749 | E13: 10814 | F13: =E13*(1+Assumptions!$G$25) -> 13517.5 | G13: =F13*(1+Assumptions!$G$26) -> 16491.35 | H13: =G13*(1+Assumptions!$G$27) -> 19459.793 | I13: =H13*(1+Assumptions!$G$28) -> 22378.762 | J13: =I13*(1+Assumptions!$G$29) -> 25064.213
A14: Partnership store YoY | B14: unavailable | C14: =C13/B13-1 -> 1.1935988 | D14: =D13/C13-1 -> 0.37882562 | E14: =E13/D13-1 -> 0.39553491 | F14: =F13/E13-1 -> 0.25 | G14: =G13/F13-1 -> 0.22 | H14: =H13/G13-1 -> 0.18 | I14: =I13/H13-1 -> 0.15 | J14: =J13/I13-1 -> 0.12
A15: Average partnership stores | B15: =AVERAGE(Assumptions!$B$16,B13) -> 2094.5 | C15: =AVERAGE(B13,C13) -> 4091 | D15: =AVERAGE(C13,D13) -> 6684.5 | E15: =AVERAGE(D13,E13) -> 9281.5 | F15: =AVERAGE(E13,F13) -> 12165.75 | G15: =AVERAGE(F13,G13) -> 15004.425 | H15: =AVERAGE(G13,H13) -> 17975.571 | I15: =AVERAGE(H13,I13) -> 20919.277 | J15: =AVERAGE(I13,J13) -> 23721.488
A16: Partnership revenue / average partner store | B16: =B18/B15 -> 1.4653913 | C16: =C18/C15 -> 1.5218225 | D16: =D18/D15 -> 1.1586941 | E16: =E18/E15 -> 1.2491181 | F16: =E16*(1+Assumptions!$G$35) -> 1.2491181 | G16: =F16*(1+Assumptions!$G$36) -> 1.2741005 | H16: =G16*(1+Assumptions!$G$37) -> 1.3123235 | I16: =H16*(1+Assumptions!$G$38) -> 1.3516932 | J16: =I16*(1+Assumptions!$G$39) -> 1.392244
A17: Partnership revenue / store YoY | B17: unavailable | C17: =C16/B16-1 -> 0.038509356 | D17: =D16/C16-1 -> -0.23861415 | E17: =E16/D16-1 -> 0.078039572 | F17: =F16/E16-1 -> 0 | G17: =G16/F16-1 -> 0.02 | H17: =H16/G16-1 -> 0.03 | I17: =I16/H16-1 -> 0.03 | J17: =J16/I16-1 -> 0.03
A18: Partnership revenue | B18: 3069.262 | C18: 6225.776 | D18: 7745.291 | E18: 11593.69 | F18: =F15*F16 -> 15196.459 | G18: =G15*G16 -> 19117.145 | H18: =H15*H16 -> 23589.765 | I18: =I15*I16 -> 28276.446 | J18: =J15*J16 -> 33026.099
A19: Partnership revenue YoY | B19: unavailable | C19: =C18/B18-1 -> 1.0284277 | D19: =D18/C18-1 -> 0.24406837 | E19: =E18/D18-1 -> 0.49686952 | F19: =F18/E18-1 -> 0.31075257 | G19: =G18/F18-1 -> 0.258 | H19: =H18/G18-1 -> 0.23395856 | I19: =I18/H18-1 -> 0.19867431 | J19: =J18/I18-1 -> 0.16797209
A21: Total net revenue | B21: =B10+B18 -> 13292.982 | C21: =C10+C18 -> 24903.166 | D21: =D10+D18 -> 34474.814 | E21: =E10+E18 -> 49288.095 | F21: =F10+F18 -> 63488.561 | G21: =G10+G18 -> 79321.299 | H21: =H10+H18 -> 96649.147 | I21: =I10+I18 -> 113951.29 | J21: =J10+J18 -> 130928.2
A22: Revenue YoY | B22: unavailable | C22: =C21/B21-1 -> 0.87340704 | D22: =D21/C21-1 -> 0.38435466 | E22: =E21/D21-1 -> 0.42968415 | F22: =F21/E21-1 -> 0.28811147 | G22: =G21/F21-1 -> 0.24937938 | H22: =H21/G21-1 -> 0.2184514 | I22: =I21/H21-1 -> 0.17902012 | J22: =J21/I21-1 -> 0.14898391
A24: Q4 avg monthly transacting customers (000) | B24: 24559 | C24: 62438 | D24: 77766 | E24: 98351 | F24: not modeled | G24: not modeled | H24: not modeled | I24: not modeled | J24: not modeled
A26: Operating expense build
A27: Cost of materials | B27: -5178.963 | C27: -10897.409 | D27: -14083.291 | E27: -18783.453 | F27: =-F21*Assumptions!$G$40 -> -24252.63 | G27: =-G21*Assumptions!$G$41 -> -30221.415 | H27: =-H21*Assumptions!$G$42 -> -36726.676 | I27: =-I21*Assumptions!$G$43 -> -43187.539 | J27: =-J21*Assumptions!$G$44 -> -49490.859
A28: Materials % of revenue | B28: =-B27/B21 -> 0.38960129 | C28: =-C27/C21 -> 0.43759131 | D28: =-D27/D21 -> 0.40850956 | E28: =-E27/E21 -> 0.38109513 | F28: =-F27/F21 -> 0.382 | G28: =-G27/G21 -> 0.381 | H28: =-H27/H21 -> 0.38 | I28: =-I27/I21 -> 0.379 | J28: =-J27/J21 -> 0.378
A29: Store rent & other operating costs | B29: -2829.987 | C29: -5167.482 | D29: -8540.683 | E29: -11241.945 | F29: =-F21*Assumptions!$G$45 -> -14475.392 | G29: =-G21*Assumptions!$G$46 -> -17847.292 | H29: =-H21*Assumptions!$G$47 -> -21456.111 | I29: =-I21*Assumptions!$G$48 -> -25069.284 | J29: =-J21*Assumptions!$G$49 -> -28542.347
A30: Store rent & operations % of revenue | B30: =-B29/B21 -> 0.21289331 | C30: =-C29/C21 -> 0.20750301 | D30: =-D29/D21 -> 0.24773688 | E30: =-E29/E21 -> 0.22808642 | F30: =-F29/F21 -> 0.228 | G30: =-G29/G21 -> 0.225 | H30: =-H29/H21 -> 0.222 | I30: =-I29/I21 -> 0.22 | J30: =-J29/J21 -> 0.218
A31: Depreciation & amortization | B31: -391.936 | C31: -604.58 | D31: -1190.037 | E31: -1557.383 | F31: =-F21*Assumptions!$G$50 -> -2031.6339 | G31: =-G21*Assumptions!$G$51 -> -2458.9603 | H31: =-H21*Assumptions!$G$52 -> -2899.4744 | I31: =-I21*Assumptions!$G$53 -> -3304.5874 | J31: =-J21*Assumptions!$G$54 -> -3665.9895
A32: D&A % of revenue | B32: =-B31/B21 -> 0.02948443 | C32: =-C31/C21 -> 0.024277234 | D32: =-D31/D21 -> 0.034519026 | E32: =-E31/E21 -> 0.031597549 | F32: =-F31/F21 -> 0.032 | G32: =-G31/G21 -> 0.031 | H32: =-H31/H21 -> 0.03 | I32: =-I31/I21 -> 0.029 | J32: =-J31/J21 -> 0.028
A33: Delivery expenses | B33: -1373.219 | C33: -2010.699 | D33: -2821.069 | E33: -6878.734 | F33: =-F21*Assumptions!$G$55 -> -8888.3985 | G33: =-G21*Assumptions!$G$56 -> -10946.339 | H33: =-H21*Assumptions!$G$57 -> -13240.933 | I33: =-I21*Assumptions!$G$58 -> -15497.375 | J33: =-J21*Assumptions!$G$59 -> -17675.307
A34: Delivery % of revenue | B34: =-B33/B21 -> 0.10330406 | C34: =-C33/C21 -> 0.080740698 | D34: =-D33/D21 -> 0.081829854 | E34: =-E33/E21 -> 0.13956177 | F34: =-F33/F21 -> 0.14 | G34: =-G33/G21 -> 0.138 | H34: =-H33/H21 -> 0.137 | I34: =-I33/I21 -> 0.136 | J34: =-J33/J21 -> 0.135
A35: Sales & marketing | B35: -570.122 | C35: -1286.523 | D35: -1920.305 | E35: -2595.705 | F35: =-F21*Assumptions!$G$60 -> -3301.4052 | G35: =-G21*Assumptions!$G$61 -> -4045.3862 | H35: =-H21*Assumptions!$G$62 -> -4832.4574 | I35: =-I21*Assumptions!$G$63 -> -5583.6132 | J35: =-J21*Assumptions!$G$64 -> -6284.5535
A36: Sales & marketing % of revenue | B36: =-B35/B21 -> 0.042888947 | C36: =-C35/C21 -> 0.051661022 | D36: =-D35/D21 -> 0.055701678 | E36: =-E35/E21 -> 0.052663934 | F36: =-F35/F21 -> 0.052 | G36: =-G35/G21 -> 0.051 | H36: =-H35/H21 -> 0.05 | I36: =-I35/I21 -> 0.049 | J36: =-J35/J21 -> 0.048
A37: General & administrative | B37: -1459.55 | C37: -1829.651 | D37: -2420.462 | E37: -3057.02 | F37: =-F21*Assumptions!$G$65 -> -3936.2908 | G37: =-G21*Assumptions!$G$66 -> -4759.2779 | H37: =-H21*Assumptions!$G$67 -> -5509.0014 | I37: =-I21*Assumptions!$G$68 -> -6495.2235 | J37: =-J21*Assumptions!$G$69 -> -7201.0509
A38: G&A % of revenue | B38: =-B37/B21 -> 0.10979854 | C38: =-C37/C21 -> 0.073470618 | D38: =-D37/D21 -> 0.070209574 | E38: =-E37/E21 -> 0.062023497 | F38: =-F37/F21 -> 0.062 | G38: =-G37/G21 -> 0.06 | H38: =-H37/H21 -> 0.057 | I38: =-I37/I21 -> 0.057 | J38: =-J37/J21 -> 0.055
A39: Preopening / impairment / other operating | B39: -333.026 | C39: -86.399 | D39: 71.102 | E39: -100.92 | F39: =-F21*Assumptions!$G$70 -> -253.95424 | G39: =-G21*Assumptions!$G$71 -> -317.2852 | H39: =-H21*Assumptions!$G$72 -> -386.59659 | I39: =-I21*Assumptions!$G$73 -> -341.85387 | J39: =-J21*Assumptions!$G$74 -> -392.78459
A40: Other operating % of revenue | B40: =-B39/B21 -> 0.025052768 | C40: =-C39/C21 -> 0.0034693982 | D40: =-D39/D21 -> -0.0020624332 | E40: =-E39/E21 -> 0.0020475533 | F40: =-F39/F21 -> 0.004 | G40: =-G39/G21 -> 0.004 | H40: =-H39/H21 -> 0.004 | I40: =-I39/I21 -> 0.003 | J40: =-J39/J21 -> 0.003
A42: Total operating expenses | B42: =SUM(B27,B29,B31,B33,B35,B37,B39) -> -12136.803 | C42: =SUM(C27,C29,C31,C33,C35,C37,C39) -> -21882.743 | D42: =SUM(D27,D29,D31,D33,D35,D37,D39) -> -30904.745 | E42: =SUM(E27,E29,E31,E33,E35,E37,E39) -> -44215.16 | F42: =SUM(F27,F29,F31,F33,F35,F37,F39) -> -57139.705 | G42: =SUM(G27,G29,G31,G33,G35,G37,G39) -> -70595.956 | H42: =SUM(H27,H29,H31,H33,H35,H37,H39) -> -85051.25 | I42: =SUM(I27,I29,I31,I33,I35,I37,I39) -> -99479.475 | J42: =SUM(J27,J29,J31,J33,J35,J37,J39) -> -113252.89
A43: Operating expenses % of revenue | B43: =-B42/B21 -> 0.91302335 | C43: =-C42/C21 -> 0.87871329 | D43: =-D42/D21 -> 0.89644414 | E43: =-E42/E21 -> 0.89707586 | F43: =-F42/F21 -> 0.9 | G43: =-G42/G21 -> 0.89 | H43: =-H42/H21 -> 0.88 | I43: =-I42/I21 -> 0.873 | J43: =-J42/J21 -> 0.865
A45: Operating income (EBIT) | B45: =B21+B42 -> 1156.179 | C45: =C21+C42 -> 3020.423 | D45: =D21+D42 -> 3570.069 | E45: =E21+E42 -> 5072.935 | F45: =F21+F42 -> 6348.8561 | G45: =G21+G42 -> 8725.3429 | H45: =H21+H42 -> 11597.898 | I45: =I21+I42 -> 14471.814 | J45: =J21+J42 -> 17675.307
A46: EBIT margin | B46: =B45/B21 -> 0.086976647 | C46: =C45/C21 -> 0.12128671 | D46: =D45/D21 -> 0.10355586 | E46: =E45/E21 -> 0.10292414 | F46: =F45/F21 -> 0.1 | G46: =G45/G21 -> 0.11 | H46: =H45/H21 -> 0.12 | I46: =I45/I21 -> 0.127 | J46: =J45/J21 -> 0.135
A48: Net interest / investment & other income | B48: -29.429 | C48: 81.741 | D48: 156.193 | E48: 207.24 | F48: =F21*Assumptions!$G$75 -> 222.20996 | G48: =G21*Assumptions!$G$76 -> 237.9639 | H48: =H21*Assumptions!$G$77 -> 241.62287 | I48: =I21*Assumptions!$G$78 -> 227.90258 | J48: =J21*Assumptions!$G$79 -> 261.8564
...

Sheet BS
A1: Balance Sheet (RMB mm)
A4: Balance Sheet | B4: 2022A | C4: 2023A | D4: 2024A | E4: 2025A | F4: 2026E | G4: 2027E | H4: 2028E | I4: 2029E | J4: 2030E
A5: Cash & restricted cash | B5: 3577.919 | C5: 3038.643 | D5: 4406.685 | E5: 2356.933 | F5: =F38+F42+F44-SUM(F8,F11,F14,F17,F20) -> 5295.3937 | G5: =G38+G42+G44-SUM(G8,G11,G14,G17,G20) -> 8812.821 | H5: =H38+H42+H44-SUM(H8,H11,H14,H17,H20) -> 14476.249 | I5: =I38+I42+I44-SUM(I8,I11,I14,I17,I20) -> 22554.937 | J5: =J38+J42+J44-SUM(J8,J11,J14,J17,J20) -> 33148.742
A6: Cash YoY | B6: unavailable | C6: =C5/B5-1 -> -0.15072337 | D6: =D5/C5-1 -> 0.45021478 | E6: =E5/D5-1 -> -0.46514602 | F6: =F5/E5-1 -> 1.2467307 | G6: =G5/F5-1 -> 0.66424282 | H6: =H5/G5-1 -> 0.64263513 | I6: =I5/H5-1 -> 0.55806499 | J6: =J5/I5-1 -> 0.46968894
A8: Short-term investments & term deposits | B8: 0 | C8: 714.019 | D8: 1527.541 | E8: 6607.423 | F8: =IS!F21*Assumptions!$G$85 -> 6348.8561 | G8: =IS!G21*Assumptions!$G$86 -> 7138.9169 | H8: =IS!H21*Assumptions!$G$87 -> 7731.9318 | I8: =IS!I21*Assumptions!$G$88 -> 7976.5902 | J8: =IS!J21*Assumptions!$G$89 -> 7855.6919
A9: Liquid investments % of revenue | B9: =B8/IS!B21 -> 0 | C9: =C8/IS!C21 -> 0.028671816 | D9: =D8/IS!D21 -> 0.044308898 | E9: =E8/IS!E21 -> 0.13405718 | F9: =F8/IS!F21 -> 0.1 | G9: =G8/IS!G21 -> 0.09 | H9: =H8/IS!H21 -> 0.08 | I9: =I8/IS!I21 -> 0.07 | J9: =J8/IS!J21 -> 0.06
A11: Operating current assets | B11: 2494.89 | C11: 4043.746 | D11: 4987.968 | E11: 6224.05 | F11: =IS!F21*Assumptions!$G$90 -> 7936.0701 | G11: =IS!G21*Assumptions!$G$91 -> 9677.1985 | H11: =IS!H21*Assumptions!$G$92 -> 11597.898 | I11: =IS!I21*Assumptions!$G$93 -> 13446.252 | J11: =IS!J21*Assumptions!$G$94 -> 15056.743
A12: Operating current assets % of revenue | B12: =B11/IS!B21 -> 0.18768475 | C12: =C11/IS!C21 -> 0.16237879 | D12: =D11/IS!D21 -> 0.14468441 | E12: =E11/IS!E21 -> 0.12627897 | F12: =F11/IS!F21 -> 0.125 | G12: =G11/IS!G21 -> 0.122 | H12: =H11/IS!H21 -> 0.12 | I12: =I11/IS!I21 -> 0.118 | J12: =J11/IS!J21 -> 0.115
A14: Property & equipment, net | B14: 1867.378 | C14: 4169.141 | D14: 5065.903 | E14: 6289.986 | F14: =E14-CF!F12+IS!F31 -> 7940.6886 | G14: =F14-CF!G12+IS!G31 -> 9844.3998 | H14: =G14-CF!H12+IS!H31 -> 11970.681 | I14: =H14-CF!I12+IS!I31 -> 14363.658 | J14: =I14-CF!J12+IS!J31 -> 16982.222
A15: PP&E % of revenue | B15: =B14/IS!B21 -> 0.14047849 | C15: =C14/IS!C21 -> 0.1674141 | D15: =D14/IS!D21 -> 0.14694504 | E15: =E14/IS!E21 -> 0.12761674 | F15: =F14/IS!F21 -> 0.12507275 | G15: =G14/IS!G21 -> 0.1241079 | H15: =H14/IS!H21 -> 0.12385708 | I15: =I14/IS!I21 -> 0.12605086 | J15: =J14/IS!J21 -> 0.12970638
A17: Operating lease ROU assets | B17: 2003.997 | C17: 5186.855 | D17: 5937.063 | E17: 7637.32 | F17: =IS!F21*Assumptions!$G$95 -> 9713.7498 | G17: =IS!G21*Assumptions!$G$96 -> 11898.195 | H17: =IS!H21*Assumptions!$G$97 -> 14207.425 | I17: =IS!I21*Assumptions!$G$98 -> 16522.937 | J17: =IS!J21*Assumptions!$G$99 -> 18722.732
A18: ROU assets % of revenue | B18: =B17/IS!B21 -> 0.15075602 | C18: =C17/IS!C21 -> 0.20828095 | D18: =D17/IS!D21 -> 0.1722145 | E18: =E17/IS!E21 -> 0.15495263 | F18: =F17/IS!F21 -> 0.153 | G18: =G17/IS!G21 -> 0.15 | H18: =H17/IS!H21 -> 0.147 | I18: =I17/IS!I21 -> 0.145 | J18: =J17/IS!J21 -> 0.143
A20: Other non-current assets | B20: 536.213 | C20: 1139.574 | D20: 1200.766 | E20: 1185.872 | F20: =IS!F21*Assumptions!$G$100 -> 1460.2369 | G20: =IS!G21*Assumptions!$G$101 -> 1745.0686 | H20: =IS!H21*Assumptions!$G$102 -> 2029.6321 | I20: =IS!I21*Assumptions!$G$103 -> 2279.0258 | J20: =IS!J21*Assumptions!$G$104 -> 2618.564
A21: Other non-current assets % of revenue | B21: =B20/IS!B21 -> 0.040338052 | C21: =C20/IS!C21 -> 0.045760206 | D21: =D20/IS!D21 -> 0.034830239 | E21: =E20/IS!E21 -> 0.024060009 | F21: =F20/IS!F21 -> 0.023 | G21: =G20/IS!G21 -> 0.022 | H21: =H20/IS!H21 -> 0.021 | I21: =I20/IS!I21 -> 0.02 | J21: =J20/IS!J21 -> 0.02
A23: Total assets | B23: =SUM(B5,B8,B11,B14,B17,B20) -> 10480.397 | C23: =SUM(C5,C8,C11,C14,C17,C20) -> 18291.978 | D23: =SUM(D5,D8,D11,D14,D17,D20) -> 23125.926 | E23: =SUM(E5,E8,E11,E14,E17,E20) -> 30301.584 | F23: =SUM(F5,F8,F11,F14,F17,F20) -> 38694.995 | G23: =SUM(G5,G8,G11,G14,G17,G20) -> 49116.6 | H23: =SUM(H5,H8,H11,H14,H17,H20) -> 62013.817 | I23: =SUM(I5,I8,I11,I14,I17,I20) -> 77143.4 | J23: =SUM(J5,J8,J11,J14,J17,J20) -> 94384.695
A24: Total assets YoY | B24: unavailable | C24: =C23/B23-1 -> 0.74535163 | D24: =D23/C23-1 -> 0.26426601 | E24: =E23/D23-1 -> 0.3102863 | F24: =F23/E23-1 -> 0.27699579 | G24: =G23/F23-1 -> 0.26932693 | H24: =H23/G23-1 -> 0.26258367 | I24: =I23/H23-1 -> 0.24397118 | J24: =J23/I23-1 -> 0.22349669
A26: Liabilities
A27: Operating current liabilities | B27: 1947.963 | C27: 3611.368 | D27: 4045.69 | E27: 5558.267 | F27: =IS!F21*Assumptions!$G$105 -> 7110.7188 | G27: =IS!G21*Assumptions!$G$106 -> 8804.6642 | H27: =IS!H21*Assumptions!$G$107 -> 10631.406 | I27: =IS!I21*Assumptions!$G$108 -> 12420.69 | J27: =IS!J21*Assumptions!$G$109 -> 14140.245
A28: Operating current liabilities % of revenue | B28: =B27/IS!B21 -> 0.14654071 | C28: =C27/IS!C21 -> 0.14501642 | D28: =D27/IS!D21 -> 0.11735205 | E28: =E27/IS!E21 -> 0.11277098 | F28: =F27/IS!F21 -> 0.112 | G28: =G27/IS!G21 -> 0.111 | H28: =H27/IS!H21 -> 0.11 | I28: =I27/IS!I21 -> 0.109 | J28: =J27/IS!J21 -> 0.108
A30: Operating lease liabilities | B30: 1905.147 | C30: 4966.165 | D30: 5673.916 | E30: 7264.161 | F30: =IS!F21*Assumptions!$G$110 -> 9269.3299 | G30: =IS!G21*Assumptions!$G$111 -> 11342.946 | H30: =IS!H21*Assumptions!$G$112 -> 13530.881 | I30: =IS!I21*Assumptions!$G$113 -> 15725.278 | J30: =IS!J21*Assumptions!$G$114 -> 17675.307
A31: Lease liabilities % of revenue | B31: =B30/IS!B21 -> 0.14331976 | C31: =C30/IS!C21 -> 0.19941902 | D31: =D30/IS!D21 -> 0.16458148 | E31: =E30/IS!E21 -> 0.14738165 | F31: =F30/IS!F21 -> 0.146 | G31: =G30/IS!G21 -> 0.143 | H31: =H30/IS!H21 -> 0.14 | I31: =I30/IS!I21 -> 0.138 | J31: =J30/IS!J21 -> 0.135
A33: Bank debt | B33: 0 | C33: 0 | D33: 333.6 | E33: 0 | F33: =Assumptions!$G$145 -> 0 | G33: =Assumptions!$G$145 -> 0 | H33: =Assumptions!$G$145 -> 0 | I33: =Assumptions!$G$145 -> 0 | J33: =Assumptions!$G$145 -> 0
A35: Other non-current liabilities | B35: 0 | C35: 0 | D35: 0 | E35: 339.797 | F35: =IS!F21*Assumptions!$G$115 -> 444.41993 | G35: =IS!G21*Assumptions!$G$116 -> 555.24909 | H35: =IS!H21*Assumptions!$G$117 -> 676.54403 | I35: =IS!I21*Assumptions!$G$118 -> 797.65902 | J35: =IS!J21*Assumptions!$G$119 -> 916.49738
A36: Other non-current liabilities % of revenue | B36: =B35/IS!B21 -> 0 | C36: =C35/IS!C21 -> 0 | D36: =D35/IS!D21 -> 0 | E36: =E35/IS!E21 -> 0.0068940989 | F36: =F35/IS!F21 -> 0.007 | G36: =G35/IS!G21 -> 0.007 | H36: =H35/IS!H21 -> 0.007 | I36: =I35/IS!I21 -> 0.007 | J36: =J35/IS!J21 -> 0.007
A38: Total liabilities | B38: =SUM(B27,B30,B33,B35) -> 3853.11 | C38: =SUM(C27,C30,C33,C35) -> 8577.533 | D38: =SUM(D27,D30,D33,D35) -> 10053.206 | E38: =SUM(E27,E30,E33,E35) -> 13162.225 | F38: =SUM(F27,F30,F33,F35) -> 16824.469 | G38: =SUM(G27,G30,G33,G35) -> 20702.859 | H38: =SUM(H27,H30,H33,H35) -> 24838.831 | I38: =SUM(I27,I30,I33,I35) -> 28943.627 | J38: =SUM(J27,J30,J33,J35) -> 32732.049
A39: Total liabilities YoY | B39: unavailable | C39: =C38/B38-1 -> 1.2261324 | D39: =D38/C38-1 -> 0.17203933 | E39: =E38/D38-1 -> 0.30925647 | F39: =F38/E38-1 -> 0.27823894 | G39: =G38/F38-1 -> 0.23052083 | H39: =H38/G38-1 -> 0.19977781 | I39: =I38/H38-1 -> 0.16525723 | J39: =J38/I38-1 -> 0.13088968
A41: Equity & checks
A42: Mezzanine equity | B42: 1578.04 | C42: 1578.04 | D42: 1514.66 | E42: 1514.66 | F42: =E42 -> 1514.66 | G42: =F42 -> 1514.66 | H42: =G42 -> 1514.66 | I42: =H42 -> 1514.66 | J42: =I42 -> 1514.66
A44: Common shareholders' equity | B44: 5049.247 | C44: 8136.405 | D44: 11558.06 | E44: 15624.699 | F44: =E44+IS!F53 -> 20355.867 | G44: =F44+IS!G53 -> 26899.08 | H44: =G44+IS!H53 -> 35660.326 | I44: =H44+IS!I53 -> 46685.113 | J44: =I44+IS!J53 -> 60137.985
A45: Common equity YoY | B45: unavailable | C45: =C44/B44-1 -> 0.61140958 | D45: =D44/C44-1 -> 0.42053647 | E45: =E44/D44-1 -> 0.35184443 | F45: =F44/E44-1 -> 0.30280056 | G45: =G44/F44-1 -> 0.32144119 | H45: =H44/G44-1 -> 0.32570798 | I45: =I44/H44-1 -> 0.30916115 | J45: =J44/I44-1 -> 0.28816193
A47: Total liabilities, mezzanine & common equity | B47: =SUM(B38,B42,B44) -> 10480.397 | C47: =SUM(C38,C42,C44) -> 18291.978 | D47: =SUM(D38,D42,D44) -> 23125.926 | E47: =SUM(E38,E42,E44) -> 30301.584 | F47: =SUM(F38,F42,F44) -> 38694.995 | G47: =SUM(G38,G42,G44) -> 49116.6 | H47: =SUM(H38,H42,H44) -> 62013.817 | I47: =SUM(I38,I42,I44) -> 77143.4 | J47: =SUM(J38,J42,J44) -> 94384.695
A48: Balance check | B48: =B23-B47 -> 0 | C48: =C23-C47 -> 0 | D48: =D23-D47 -> 0 | E48: =E23-E47 -> 0 | F48: =F23-F47 -> 0 | G48: =G23-G47 -> 0 | H48: =H23-H47 -> 0 | I48: =I23-I47 -> 0 | J48: =J23-J47 -> 0
A50: Net debt / (net cash & liquid investments) | B50: =B33-B5-B8 -> -3577.919 | C50: =C33-C5-C8 -> -3752.662 | D50: =D33-D5-D8 -> -5600.626 | E50: =E33-E5-E8 -> -8964.356 | F50: =F33-F5-F8 -> -11644.25 | G50: =G33-G5-G8 -> -15951.738 | H50: =H33-H5-H8 -> -22208.181 | I50: =I33-I5-I8 -> -30531.527 | J50: =J33-J5-J8 -> -41004.434

Sheet CF
A1: Cash Flow Statement (RMB mm)
A4: Cash Flow | B4: 2022A | C4: 2023A | D4: 2024A | E4: 2025A | F4: 2026E | G4: 2027E | H4: 2028E | I4: 2029E | J4: 2030E
A5: Net income | B5: =IS!B53 -> 488.246 | C5: =IS!C53 -> 2844.037 | D5: =IS!D53 -> 2955.709 | E5: =IS!E53 -> 3600.382 | F5: =IS!F53 -> 4731.1675 | G5: =IS!G53 -> 6543.2139 | H5: =IS!H53 -> 8761.2452 | I5: =IS!I53 -> 11024.787 | J5: =IS!J53 -> 13452.872
A6: D&A | B6: =-IS!B31 -> 391.936 | C6: =-IS!C31 -> 604.58 | D6: =-IS!D31 -> 1190.037 | E6: =-IS!E31 -> 1557.383 | F6: =-IS!F31 -> 2031.6339 | G6: =-IS!G31 -> 2458.9603 | H6: =-IS!H31 -> 2899.4744 | I6: =-IS!I31 -> 3304.5874 | J6: =-IS!J31 -> 3665.9895
A7: Working capital & other operating adjustments | B7: =B8-B5-B6 -> -860.364 | C7: =C8-C5-C6 -> -548.192 | D7: =D8-D5-D6 -> 83.526 | E7: =E8-E5-E6 -> 933.297 | F7: =-((BS!F11-BS!F27)-(BS!E11-BS!E27))+(BS!F35-BS!E35) -> -54.945364 | G7: =-((BS!G11-BS!G27)-(BS!F11-BS!F27))+(BS!G35-BS!F35) -> 63.646169 | H7: =-((BS!H11-BS!H27)-(BS!G11-BS!G27))+(BS!H35-BS!G35) -> 27.337753 | I7: =-((BS!I11-BS!I27)-(BS!H11-BS!H27))+(BS!I35-BS!H35) -> 62.044864 | J7: =-((BS!J11-BS!J27)-(BS!I11-BS!I27))+(BS!J35-BS!I35) -> 227.90258
A8: Net cash from operating activities (CFO) | B8: 19.818 | C8: 2900.425 | D8: 4229.272 | E8: 6091.062 | F8: =F5+F6+F7 -> 6707.8561 | G8: =G5+G6+G7 -> 9065.8204 | H8: =H5+H6+H7 -> 11688.057 | I8: =I5+I6+I7 -> 14391.419 | J8: =J5+J6+J7 -> 17346.764
A9: CFO margin | B9: =B8/IS!B21 -> 0.0014908619 | C9: =C8/IS!C21 -> 0.11646812 | D9: =D8/IS!D21 -> 0.12267715 | E9: =E8/IS!E21 -> 0.1235808 | F9: =F8/IS!F21 -> 0.10565456 | G9: =G8/IS!G21 -> 0.11429238 | H9: =H8/IS!H21 -> 0.12093286 | I9: =I8/IS!I21 -> 0.12629449 | J9: =J8/IS!J21 -> 0.13249067
A11: Investing activities
A12: Purchases of property & equipment (CapEx) | B12: -781.676 | C12: -2750.22 | D12: -2301.791 | E12: -2623.694 | F12: =-IS!F21*Assumptions!$G$120 -> -3682.3365 | G12: =-IS!G21*Assumptions!$G$121 -> -4362.6714 | H12: =-IS!H21*Assumptions!$G$122 -> -5025.7557 | I12: =-IS!I21*Assumptions!$G$123 -> -5697.5644 | J12: =-IS!J21*Assumptions!$G$124 -> -6284.5535
A13: Other investing activities | B13: =B14-B12 -> -16.37 | C13: =C14-C12 -> -696.879 | D13: =D14-D12 -> -908.015 | E13: =E14-E12 -> -5162.809 | F13: =-(BS!F8-BS!E8)-(BS!F20-BS!E20)+(BS!F30-BS!E30)-(BS!F17-BS!E17) -> -87.058893 | G13: =-(BS!G8-BS!F8)-(BS!G20-BS!F20)+(BS!G30-BS!F30)-(BS!G17-BS!F17) -> -1185.7217 | H13: =-(BS!H8-BS!G8)-(BS!H20-BS!G20)+(BS!H30-BS!G30)-(BS!H17-BS!G17) -> -998.87335 | I13: =-(BS!I8-BS!H8)-(BS!I20-BS!H20)+(BS!I30-BS!H30)-(BS!I17-BS!H17) -> -615.16711 | J13: =-(BS!J8-BS!I8)-(BS!J20-BS!I20)+(BS!J30-BS!I30)-(BS!J17-BS!I17) -> -468.40637
A14: Net cash from investing activities (CFI) | B14: -798.046 | C14: -3447.099 | D14: -3209.806 | E14: -7786.503 | F14: =F12+F13 -> -3769.3954 | G14: =G12+G13 -> -5548.3931 | H14: =H12+H13 -> -6024.629 | I14: =I12+I13 -> -6312.7316 | J14: =J12+J13 -> -6752.9599
A16: Financing activities
A17: Debt / equity / other financing | B17: =B18 -> -2276.26 | C17: =C18 -> 0 | D17: =D18 -> 333.6 | E17: =E18 -> -333.6 | F17: =(BS!F33-BS!E33)+(BS!F42-BS!E42)+(BS!F44-BS!E44)-IS!F53 -> 0 | G17: =(BS!G33-BS!F33)+(BS!G42-BS!F42)+(BS!G44-BS!F44)-IS!G53 -> 0 | H17: =(BS!H33-BS!G33)+(BS!H42-BS!G42)+(BS!H44-BS!G44)-IS!H53 -> 0 | I17: =(BS!I33-BS!H33)+(BS!I42-BS!H42)+(BS!I44-BS!H44)-IS!I53 -> 0 | J17: =(BS!J33-BS!I33)+(BS!J42-BS!I42)+(BS!J44-BS!I44)-IS!J53 -> 0
A18: Net cash from financing activities (CFF) | B18: -2276.26 | C18: 0 | D18: 333.6 | E18: -333.6 | F18: =F17 -> 0 | G18: =G17 -> 0 | H18: =H17 -> 0 | I18: =I17 -> 0 | J18: =J17 -> 0
A20: FX effect on cash | B20: 77.133 | C20: 7.398 | D20: 14.976 | E20: -20.711 | F20: =BS!E5*Assumptions!$G$125 -> 0 | G20: =BS!F5*Assumptions!$G$126 -> 0 | H20: =BS!G5*Assumptions!$G$127 -> 0 | I20: =BS!H5*Assumptions!$G$128 -> 0 | J20: =BS!I5*Assumptions!$G$129 -> 0
A21: Net change in cash & restricted cash | B21: =B8+B14+B18+B20 -> -2977.355 | C21: =C8+C14+C18+C20 -> -539.276 | D21: =D8+D14+D18+D20 -> 1368.042 | E21: =E8+E14+E18+E20 -> -2049.752 | F21: =F8+F14+F18+F20 -> 2938.4607 | G21: =G8+G14+G18+G20 -> 3517.4273 | H21: =H8+H14+H18+H20 -> 5663.4284 | I21: =I8+I14+I18+I20 -> 8078.6879 | J21: =J8+J14+J18+J20 -> 10593.805
A22: Beginning cash & restricted cash | B22: 6555.274 | C22: 3577.919 | D22: 3038.643 | E22: 4406.685 | F22: =BS!E5 -> 2356.933 | G22: =BS!F5 -> 5295.3937 | H22: =BS!G5 -> 8812.821 | I22: =BS!H5 -> 14476.249 | J22: =BS!I5 -> 22554.937
A23: Ending cash & restricted cash | B23: 3577.919 | C23: 3038.643 | D23: 4406.685 | E23: 2356.933 | F23: =F22+F21 -> 5295.3937 | G23: =G22+G21 -> 8812.821 | H23: =H22+H21 -> 14476.249 | I23: =I22+I21 -> 22554.937 | J23: =J22+J21 -> 33148.742
A24: Cash roll-forward check | B24: =B23-(B22+B21) -> 0 | C24: =C23-(C22+C21) -> 0 | D24: =D23-(D22+D21) -> 0 | E24: =E23-(E22+E21) -> 0 | F24: =F23-(F22+F21) -> 0 | G24: =G23-(G22+G21) -> 0 | H24: =H23-(H22+H21) -> 0 | I24: =I23-(I22+I21) -> 0 | J24: =J23-(J22+J21) -> 0
A25: Ending cash vs BS check | B25: =B23-BS!B5 -> 0 | C25: =C23-BS!C5 -> 0 | D25: =D23-BS!D5 -> 0 | E25: =E23-BS!E5 -> 0 | F25: =F23-BS!F5 -> 0 | G25: =G23-BS!G5 -> 0 | H25: =H23-BS!H5 -> 1.4551915e-11 | I25: =I23-BS!I5 -> 0 | J25: =J23-BS!J5 -> 0

Sheet DCF
A1: Luckin Coffee Inc. - DCF (RMB mm, except per ADS)
A2: As of 2026-09-06 | Forecast assumptions are provisional
A4: Case selector | B4: =Assumptions!$B$4 -> 2
A5: Case name | B5: =CHOOSE($B$4,"Bear","Base","Bull") -> Base
A7: Market data & equity bridge inputs
A8: Current price (USD / ADS) | B8: =Assumptions!$G$141 -> 34.81
A9: Basic ADS equivalent shares (mm) | B9: =Assumptions!$G$143 -> 286.78923
A10: Market capitalization (USD mm) | B10: =B8*B9 -> 9983.1329
A11: CNY per USD | B11: =Assumptions!$G$142 -> 7.0063
A12: Market capitalization (RMB mm) | B12: =B10*B11 -> 69944.824
A13: Diluted ADS equivalent shares (mm) | B13: =Assumptions!$G$144 -> 321.02163
A14: Total debt | B14: =Assumptions!$G$145 -> 0
A15: Cash & liquid investments | B15: =Assumptions!$G$146 -> 8901.535
A16: Mezzanine equity | B16: =Assumptions!$G$147 -> 1514.66
A17: Net debt + mezzanine adjustment | B17: =B14-B15+B16 -> -7386.875
A18: Current enterprise value | B18: =B12+B17 -> 62557.949
A20: WACC support (inside DCF)
A22: Risk-free rate | B22: =Assumptions!$G$136 -> 0.043
A23: Beta | B23: =Assumptions!$G$137 -> 1.05
A24: Equity risk premium | B24: =Assumptions!$G$138 -> 0.055
A25: Country / listing risk premium | B25: =Assumptions!$G$139 -> 0.015
A26: Cost of equity | B26: =B22+B23*B24+B25 -> 0.11575
A27: Pre-tax cost of debt | B27: =Assumptions!$G$140 -> 0.055
A28: Terminal tax rate | B28: =Assumptions!$G$84 -> 0.25
A29: After-tax cost of debt | B29: =B27*(1-B28) -> 0.04125
A30: Capital base | B30: =B12+B14 -> 69944.824
A31: Equity weight | B31: =IF(B30=0,1,B12/B30) -> 1
A32: Debt weight | B32: =IF(B30=0,0,B14/B30) -> 0
A33: WACC | B33: =B26*B31+B29*B32 -> 0.11575
A36: Unlevered FCF build
A37: DCF valuation | B37: 2026E | C37: 2027E | D37: 2028E | E37: 2029E | F37: 2030E
A39: Revenue | B39: =IS!F21 -> 63488.561 | C39: =IS!G21 -> 79321.299 | D39: =IS!H21 -> 96649.147 | E39: =IS!I21 -> 113951.29 | F39: =IS!J21 -> 130928.2
A40: EBIT | B40: =IS!F45 -> 6348.8561 | C40: =IS!G45 -> 8725.3429 | D40: =IS!H45 -> 11597.898 | E40: =IS!I45 -> 14471.814 | F40: =IS!J45 -> 17675.307
A41: Cash taxes on EBIT | B41: =-B40*Assumptions!$G$80 -> -1777.6797 | C41: =-C40*Assumptions!$G$81 -> -2355.8426 | D41: =-D40*Assumptions!$G$82 -> -3015.4534 | E41: =-E40*Assumptions!$G$83 -> -3617.9534 | F41: =-F40*Assumptions!$G$84 -> -4418.8267
A42: NOPAT | B42: =B40+B41 -> 4571.1764 | C42: =C40+C41 -> 6369.5003 | D42: =D40+D41 -> 8582.4443 | E42: =E40+E41 -> 10853.86 | F42: =F40+F41 -> 13256.48
A43: D&A | B43: =-IS!F31 -> 2031.6339 | C43: =-IS!G31 -> 2458.9603 | D43: =-IS!H31 -> 2899.4744 | E43: =-IS!I31 -> 3304.5874 | F43: =-IS!J31 -> 3665.9895
A44: CapEx | B44: =-CF!F12 -> 3682.3365 | C44: =-CF!G12 -> 4362.6714 | D44: =-CF!H12 -> 5025.7557 | E44: =-CF!I12 -> 5697.5644 | F44: =-CF!J12 -> 6284.5535
A45: Change in operating NWC | B45: =(BS!F11-BS!F27)-(BS!E11-BS!E27) -> 159.56829 | C45: =(BS!G11-BS!G27)-(BS!F11-BS!F27) -> 47.182999 | D45: =(BS!H11-BS!H27)-(BS!G11-BS!G27) -> 93.957186 | E45: =(BS!I11-BS!I27)-(BS!H11-BS!H27) -> 59.070126 | F45: =(BS!J11-BS!J27)-(BS!I11-BS!I27) -> -109.06422
A46: Unlevered FCF | B46: =B42+B43-B44-B45 -> 2760.9055 | C46: =C42+C43-C44-C45 -> 4418.6061 | D46: =D42+D43-D44-D45 -> 6362.2059 | E46: =E42+E43-E44-E45 -> 8401.8131 | F46: =F42+F43-F44-F45 -> 10746.98
A47: Mid-year discount period | B47: =Assumptions!$G$130 -> 0.5 | C47: =Assumptions!$G$131 -> 1.5 | D47: =Assumptions!$G$132 -> 2.5 | E47: =Assumptions!$G$133 -> 3.5 | F47: =Assumptions!$G$134 -> 4.5
...

Sheet Sensitivity
A1: Luckin Coffee Inc. - DCF Sensitivity (USD / ADS)
A2: All 75 output cells contain full DCF formulas; each center cell equals DCF Base case.
A4: WACC vs terminal growth
A5: wacc_axis / terminal_growth_axis | B5: =Assumptions!$D$156 -> 0.015 | C5: =Assumptions!$D$157 -> 0.02 | D5: =Assumptions!$D$158 -> 0.025 | E5: =Assumptions!$D$159 -> 0.03 | F5: =Assumptions!$D$160 -> 0.035
A6: =Assumptions!$D$151 -> 0.10575 | B6: =((DCF!$B$46/(1+Assumptions!$D$151)^DCF!$B$47+DCF!$C$46/(1+Assumptions!$D$151)^DCF!$C$47+DCF!$D$46/(1+Assumptions!$D$151)^DCF!$D$47+DCF!$E$46/(1+Assumptions!$D$151)^DCF!$E$47+DCF!$F$46/(1+Assumptions!$D$151)^DCF!$F$47+DCF!$F$46*(1+Assumptions!$D$156)/(Assumptions!$D$151-Assumptions!$D$156)/(1+Assumptions!$D$151)^DCF!$F$47)-DCF!$B$62+DCF!$B$63-DCF!$B$64)/DCF!$B$66/DCF!$B$68 -> 48.004266 | C6: =((DCF!$B$46/(1+Assumptions!$D$151)^DCF!$B$47+DCF!$C$46/(1+Assumptions!$D$151)^DCF!$C$47+DCF!$D$46/(1+Assumptions!$D$151)^DCF!$D$47+DCF!$E$46/(1+Assumptions!$D$151)^DCF!$E$47+DCF!$F$46/(1+Assumptions!$D$151)^DCF!$F$47+DCF!$F$46*(1+Assumptions!$D$157)/(Assumptions!$D$151-Assumptions!$D$157)/(1+Assumptions!$D$151)^DCF!$F$47)-DCF!$B$62+DCF!$B$63-DCF!$B$64)/DCF!$B$66/DCF!$B$68 -> 50.163767 | D6: =((DCF!$B$46/(1+Assumptions!$D$151)^DCF!$B$47+DCF!$C$46/(1+Assumptions!$D$151)^DCF!$C$47+DCF!$D$46/(1+Assumptions!$D$151)^DCF!$D$47+DCF!$E$46/(1+Assumptions!$D$151)^DCF!$E$47+DCF!$F$46/(1+Assumptions!$D$151)^DCF!$F$47+DCF!$F$46*(1+Assumptions!$D$158)/(Assumptions!$D$151-Assumptions!$D$158)/(1+Assumptions!$D$151)^DCF!$F$47)-DCF!$B$62+DCF!$B$63-DCF!$B$64)/DCF!$B$66/DCF!$B$68 -> 52.590698 | E6: =((DCF!$B$46/(1+Assumptions!$D$151)^DCF!$B$47+DCF!$C$46/(1+Assumptions!$D$151)^DCF!$C$47+DCF!$D$46/(1+Assumptions!$D$151)^DCF!$D$47+DCF!$E$46/(1+Assumptions!$D$151)^DCF!$E$47+DCF!$F$46/(1+Assumptions!$D$151)^DCF!$F$47+DCF!$F$46*(1+Assumptions!$D$159)/(Assumptions!$D$151-Assumptions!$D$159)/(1+Assumptions!$D$151)^DCF!$F$47)-DCF!$B$62+DCF!$B$63-DCF!$B$64)/DCF!$B$66/DCF!$B$68 -> 55.338016 | F6: =((DCF!$B$46/(1+Assumptions!$D$151)^DCF!$B$47+DCF!$C$46/(1+Assumptions!$D$151)^DCF!$C$47+DCF!$D$46/(1+Assumptions!$D$151)^DCF!$D$47+DCF!$E$46/(1+Assumptions!$D$151)^DCF!$E$47+DCF!$F$46/(1+Assumptions!$D$151)^DCF!$F$47+DCF!$F$46*(1+Assumptions!$D$160)/(Assumptions!$D$151-Assumptions!$D$160)/(1+Assumptions!$D$151)^DCF!$F$47)-DCF!$B$62+DCF!$B$63-DCF!$B$64)/DCF!$B$66/DCF!$B$68 -> 58.473647
A7: =Assumptions!$D$152 -> 0.11075 | B7: =((DCF!$B$46/(1+Assumptions!$D$152)^DCF!$B$47+DCF!$C$46/(1+Assumptions!$D$152)^DCF!$C$47+DCF!$D$46/(1+Assumptions!$D$152)^DCF!$D$47+DCF!$E$46/(1+Assumptions!$D$152)^DCF!$E$47+DCF!$F$46/(1+Assumptions!$D$152)^DCF!$F$47+DCF!$F$46*(1+Assumptions!$D$156)/(Assumptions!$D$152-Assumptions!$D$156)/(1+Assumptions!$D$152)^DCF!$F$47)-DCF!$B$62+DCF!$B$63-DCF!$B$64)/DCF!$B$66/DCF!$B$68 -> 45.440511 | C7: =((DCF!$B$46/(1+Assumptions!$D$152)^DCF!$B$47+DCF!$C$46/(1+Assumptions!$D$152)^DCF!$C$47+DCF!$D$46/(1+Assumptions!$D$152)^DCF!$D$47+DCF!$E$46/(1+Assumptions!$D$152)^DCF!$E$47+DCF!$F$46/(1+Assumptions!$D$152)^DCF!$F$47+DCF!$F$46*(1+Assumptions!$D$157)/(Assumptions!$D$152-Assumptions!$D$157)/(1+Assumptions!$D$152)^DCF!$F$47)-DCF!$B$62+DCF!$B$63-DCF!$B$64)/DCF!$B$66/DCF!$B$68 -> 47.344178 | D7: =((DCF!$B$46/(1+Assumptions!$D$152)^DCF!$B$47+DCF!$C$46/(1+Assumptions!$D$152)^DCF!$C$47+DCF!$D$46/(1+Assumptions!$D$152)^DCF!$D$47+DCF!$E$46/(1+Assumptions!$D$152)^DCF!$E$47+DCF!$F$46/(1+Assumptions!$D$152)^DCF!$F$47+DCF!$F$46*(1+Assumptions!$D$158)/(Assumptions!$D$152-Assumptions!$D$158)/(1+Assumptions!$D$152)^DCF!$F$47)-DCF!$B$62+DCF!$B$63-DCF!$B$64)/DCF!$B$66/DCF!$B$68 -> 49.469846 | E7: =((DCF!$B$46/(1+Assumptions!$D$152)^DCF!$B$47+DCF!$C$46/(1+Assumptions!$D$152)^DCF!$C$47+DCF!$D$46/(1+Assumptions!$D$152)^DCF!$D$47+DCF!$E$46/(1+Assumptions!$D$152)^DCF!$E$47+DCF!$F$46/(1+Assumptions!$D$152)^DCF!$F$47+DCF!$F$46*(1+Assumptions!$D$159)/(Assumptions!$D$152-Assumptions!$D$159)/(1+Assumptions!$D$152)^DCF!$F$47)-DCF!$B$62+DCF!$B$63-DCF!$B$64)/DCF!$B$66/DCF!$B$68 -> 51.858755 | F7: =((DCF!$B$46/(1+Assumptions!$D$152)^DCF!$B$47+DCF!$C$46/(1+Assumptions!$D$152)^DCF!$C$47+DCF!$D$46/(1+Assumptions!$D$152)^DCF!$D$47+DCF!$E$46/(1+Assumptions!$D$152)^DCF!$E$47+DCF!$F$46/(1+Assumptions!$D$152)^DCF!$F$47+DCF!$F$46*(1+Assumptions!$D$160)/(Assumptions!$D$152-Assumptions!$D$160)/(1+Assumptions!$D$152)^DCF!$F$47)-DCF!$B$62+DCF!$B$63-DCF!$B$64)/DCF!$B$66/DCF!$B$68 -> 54.563032
A8: =Assumptions!$D$153 -> 0.11575 | B8: =((DCF!$B$46/(1+Assumptions!$D$153)^DCF!$B$47+DCF!$C$46/(1+Assumptions!$D$153)^DCF!$C$47+DCF!$D$46/(1+Assumptions!$D$153)^DCF!$D$47+DCF!$E$46/(1+Assumptions!$D$153)^DCF!$E$47+DCF!$F$46/(1+Assumptions!$D$153)^DCF!$F$47+DCF!$F$46*(1+Assumptions!$D$156)/(Assumptions!$D$153-Assumptions!$D$156)/(1+Assumptions!$D$153)^DCF!$F$47)-DCF!$B$62+DCF!$B$63-DCF!$B$64)/DCF!$B$66/DCF!$B$68 -> 43.135133 | C8: =((DCF!$B$46/(1+Assumptions!$D$153)^DCF!$B$47+DCF!$C$46/(1+Assumptions!$D$153)^DCF!$C$47+DCF!$D$46/(1+Assumptions!$D$153)^DCF!$D$47+DCF!$E$46/(1+Assumptions!$D$153)^DCF!$E$47+DCF!$F$46/(1+Assumptions!$D$153)^DCF!$F$47+DCF!$F$46*(1+Assumptions!$D$157)/(Assumptions!$D$153-Assumptions!$D$157)/(1+Assumptions!$D$153)^DCF!$F$47)-DCF!$B$62+DCF!$B$63-DCF!$B$64)/DCF!$B$66/DCF!$B$68 -> 44.823106 | D8: =((DCF!$B$46/(1+Assumptions!$D$153)^DCF!$B$47+DCF!$C$46/(1+Assumptions!$D$153)^DCF!$C$47+DCF!$D$46/(1+Assumptions!$D$153)^DCF!$D$47+DCF!$E$46/(1+Assumptions!$D$153)^DCF!$E$47+DCF!$F$46/(1+Assumptions!$D$153)^DCF!$F$47+DCF!$F$46*(1+Assumptions!$D$158)/(Assumptions!$D$153-Assumptions!$D$158)/(1+Assumptions!$D$153)^DCF!$F$47)-DCF!$B$62+DCF!$B$63-DCF!$B$64)/DCF!$B$66/DCF!$B$68 -> 46.697081 | E8: =((DCF!$B$46/(1+Assumptions!$D$153)^DCF!$B$47+DCF!$C$46/(1+Assumptions!$D$153)^DCF!$C$47+DCF!$D$46/(1+Assumptions!$D$153)^DCF!$D$47+DCF!$E$46/(1+Assumptions!$D$153)^DCF!$E$47+DCF!$F$46/(1+Assumptions!$D$153)^DCF!$F$47+DCF!$F$46*(1+Assumptions!$D$159)/(Assumptions!$D$153-Assumptions!$D$159)/(1+Assumptions!$D$153)^DCF!$F$47)-DCF!$B$62+DCF!$B$63-DCF!$B$64)/DCF!$B$66/DCF!$B$68 -> 48.789596 | F8: =((DCF!$B$46/(1+Assumptions!$D$153)^DCF!$B$47+DCF!$C$46/(1+Assumptions!$D$153)^DCF!$C$47+DCF!$D$46/(1+Assumptions!$D$153)^DCF!$D$47+DCF!$E$46/(1+Assumptions!$D$153)^DCF!$E$47+DCF!$F$46/(1+Assumptions!$D$153)^DCF!$F$47+DCF!$F$46*(1+Assumptions!$D$160)/(Assumptions!$D$153-Assumptions!$D$160)/(1+Assumptions!$D$153)^DCF!$F$47)-DCF!$B$62+DCF!$B$63-DCF!$B$64)/DCF!$B$66/DCF!$B$68 -> 51.141245
A9: =Assumptions!$D$154 -> 0.12075 | B9: =((DCF!$B$46/(1+Assumptions!$D$154)^DCF!$B$47+DCF!$C$46/(1+Assumptions!$D$154)^DCF!$C$47+DCF!$D$46/(1+Assumptions!$D$154)^DCF!$D$47+DCF!$E$46/(1+Assumptions!$D$154)^DCF!$E$47+DCF!$F$46/(1+Assumptions!$D$154)^DCF!$F$47+DCF!$F$46*(1+Assumptions!$D$156)/(Assumptions!$D$154-Assumptions!$D$156)/(1+Assumptions!$D$154)^DCF!$F$47)-DCF!$B$62+DCF!$B$63-DCF!$B$64)/DCF!$B$66/DCF!$B$68 -> 41.051401 | C9: =((DCF!$B$46/(1+Assumptions!$D$154)^DCF!$B$47+DCF!$C$46/(1+Assumptions!$D$154)^DCF!$C$47+DCF!$D$46/(1+Assumptions!$D$154)^DCF!$D$47+DCF!$E$46/(1+Assumptions!$D$154)^DCF!$E$47+DCF!$F$46/(1+Assumptions!$D$154)^DCF!$F$47+DCF!$F$46*(1+Assumptions!$D$157)/(Assumptions!$D$154-Assumptions!$D$157)/(1+Assumptions!$D$154)^DCF!$F$47)-DCF!$B$62+DCF!$B$63-DCF!$B$64)/DCF!$B$66/DCF!$B$68 -> 42.556022 | D9: =((DCF!$B$46/(1+Assumptions!$D$154)^DCF!$B$47+DCF!$C$46/(1+Assumptions!$D$154)^DCF!$C$47+DCF!$D$46/(1+Assumptions!$D$154)^DCF!$D$47+DCF!$E$46/(1+Assumptions!$D$154)^DCF!$E$47+DCF!$F$46/(1+Assumptions!$D$154)^DCF!$F$47+DCF!$F$46*(1+Assumptions!$D$158)/(Assumptions!$D$154-Assumptions!$D$158)/(1+Assumptions!$D$154)^DCF!$F$47)-DCF!$B$62+DCF!$B$63-DCF!$B$64)/DCF!$B$66/DCF!$B$68 -> 44.217785 | E9: =((DCF!$B$46/(1+Assumptions!$D$154)^DCF!$B$47+DCF!$C$46/(1+Assumptions!$D$154)^DCF!$C$47+DCF!$D$46/(1+Assumptions!$D$154)^DCF!$D$47+DCF!$E$46/(1+Assumptions!$D$154)^DCF!$E$47+DCF!$F$46/(1+Assumptions!$D$154)^DCF!$F$47+DCF!$F$46*(1+Assumptions!$D$159)/(Assumptions!$D$154-Assumptions!$D$159)/(1+Assumptions!$D$154)^DCF!$F$47)-DCF!$B$62+DCF!$B$63-DCF!$B$64)/DCF!$B$66/DCF!$B$68 -> 46.062662 | F9: =((DCF!$B$46/(1+Assumptions!$D$154)^DCF!$B$47+DCF!$C$46/(1+Assumptions!$D$154)^DCF!$C$47+DCF!$D$46/(1+Assumptions!$D$154)^DCF!$D$47+DCF!$E$46/(1+Assumptions!$D$154)^DCF!$E$47+DCF!$F$46/(1+Assumptions!$D$154)^DCF!$F$47+DCF!$F$46*(1+Assumptions!$D$160)/(Assumptions!$D$154-Assumptions!$D$160)/(1+Assumptions!$D$154)^DCF!$F$47)-DCF!$B$62+DCF!$B$63-DCF!$B$64)/DCF!$B$66/DCF!$B$68 -> 48.122685
A10: =Assumptions!$D$155 -> 0.12575 | B10: =((DCF!$B$46/(1+Assumptions!$D$155)^DCF!$B$47+DCF!$C$46/(1+Assumptions!$D$155)^DCF!$C$47+DCF!$D$46/(1+Assumptions!$D$155)^DCF!$D$47+DCF!$E$46/(1+Assumptions!$D$155)^DCF!$E$47+DCF!$F$46/(1+Assumptions!$D$155)^DCF!$F$47+DCF!$F$46*(1+Assumptions!$D$156)/(Assumptions!$D$155-Assumptions!$D$156)/(1+Assumptions!$D$155)^DCF!$F$47)-DCF!$B$62+DCF!$B$63-DCF!$B$64)/DCF!$B$66/DCF!$B$68 -> 39.159219 | C10: =((DCF!$B$46/(1+Assumptions!$D$155)^DCF!$B$47+DCF!$C$46/(1+Assumptions!$D$155)^DCF!$C$47+DCF!$D$46/(1+Assumptions!$D$155)^DCF!$D$47+DCF!$E$46/(1+Assumptions!$D$155)^DCF!$E$47+DCF!$F$46/(1+Assumptions!$D$155)^DCF!$F$47+DCF!$F$46*(1+Assumptions!$D$157)/(Assumptions!$D$155-Assumptions!$D$157)/(1+Assumptions!$D$155)^DCF!$F$47)-DCF!$B$62+DCF!$B$63-DCF!$B$64)/DCF!$B$66/DCF!$B$68 -> 40.506824 | D10: =((DCF!$B$46/(1+Assumptions!$D$155)^DCF!$B$47+DCF!$C$46/(1+Assumptions!$D$155)^DCF!$C$47+DCF!$D$46/(1+Assumptions!$D$155)^DCF!$D$47+DCF!$E$46/(1+Assumptions!$D$155)^DCF!$E$47+DCF!$F$46/(1+Assumptions!$D$155)^DCF!$F$47+DCF!$F$46*(1+Assumptions!$D$158)/(Assumptions!$D$155-Assumptions!$D$158)/(1+Assumptions!$D$155)^DCF!$F$47)-DCF!$B$62+DCF!$B$63-DCF!$B$64)/DCF!$B$66/DCF!$B$68 -> 41.988186 | E10: =((DCF!$B$46/(1+Assumptions!$D$155)^DCF!$B$47+DCF!$C$46/(1+Assumptions!$D$155)^DCF!$C$47+DCF!$D$46/(1+Assumptions!$D$155)^DCF!$D$47+DCF!$E$46/(1+Assumptions!$D$155)^DCF!$E$47+DCF!$F$46/(1+Assumptions!$D$155)^DCF!$F$47+DCF!$F$46*(1+Assumptions!$D$159)/(Assumptions!$D$155-Assumptions!$D$159)/(1+Assumptions!$D$155)^DCF!$F$47)-DCF!$B$62+DCF!$B$63-DCF!$B$64)/DCF!$B$66/DCF!$B$68 -> 43.624259 | F10: =((DCF!$B$46/(1+Assumptions!$D$155)^DCF!$B$47+DCF!$C$46/(1+Assumptions!$D$155)^DCF!$C$47+DCF!$D$46/(1+Assumptions!$D$155)^DCF!$D$47+DCF!$E$46/(1+Assumptions!$D$155)^DCF!$E$47+DCF!$F$46/(1+Assumptions!$D$155)^DCF!$F$47+DCF!$F$46*(1+Assumptions!$D$160)/(Assumptions!$D$155-Assumptions!$D$160)/(1+Assumptions!$D$155)^DCF!$F$47)-DCF!$B$62+DCF!$B$63-DCF!$B$64)/DCF!$B$66/DCF!$B$68 -> 45.440616
A13: Revenue growth delta vs EBIT margin delta
A14: revenue_growth_delta_axis / ebit_margin_delta_axis | B14: =Assumptions!$D$166 -> -0.03 | C14: =Assumptions!$D$167 -> -0.015 | D14: =Assumptions!$D$168 -> 0 | E14: =Assumptions!$D$169 -> 0.015 | F14: =Assumptions!$D$170 -> 0.03
A15: =Assumptions!$D$161 -> -0.04 | B15: =((((DCF!$B$39*(1+Assumptions!$D$161)^1)*(DCF!$B$40/DCF!$B$39+Assumptions!$D$166)*(1-(-DCF!$B$41/DCF!$B$40))+DCF!$B$43*(1+Assumptions!$D$161)^1-DCF!$B$44*(1+Assumptions!$D$161)^1-DCF!$B$45*(1+Assumptions!$D$161)^1)/(1+DCF!$B$33)^DCF!$B$47+((DCF!$C$39*(1+Assumptions!$D$161)^2)*(DCF!$C$40/DCF!$C$39+Assumptions!$D$166)*(1-(-DCF!$C$41/DCF!$C$40))+DCF!$C$43*(1+Assumptions!$D$161)^2-DCF!$C$44*(1+Assumptions!$D$161)^2-DCF!$C$45*(1+Assumptions!$D$161)^2)/(1+DCF!$B$33)^DCF!$C$47+((DCF!$D$39*(1+Assumptions!$D$161)^3)*(DCF!$D$40/DCF!$D$39+Assumptions!$D$166)*(1-(-DCF!$D$41/DCF!$D$40))+DCF!$D$43*(1+Assumptions!$D$161)^3-DCF!$D$44*(1+Assumptions!$D$161)^3-DCF!$D$45*(1+Assumptions!$D$161)^3)/(1+DCF!$B$33)^DCF!$D$47+((DCF!$E$39*(1+Assumptions!$D$161)^4)*(DCF!$E$40/DCF!$E$39+Assumptions!$D$166)*(1-(-DCF!$E$41/DCF!$E$40))+DCF!$E$43*(1+Assumptions!$D$161)^4-DCF!$E$44*(1+Assumptions!$D$161)^4-DCF!$E$45*(1+Assumptions!$D$161)^4)/(1+DCF!$B$33)^DCF!$E$47+((DCF!$F$39*(1+Assumptions!$D$161)^5)*(DCF!$F$40/DCF!$F$39+Assumptions!$D$166)*(1-(-DCF!$F$41/DCF!$F$40))+DCF!$F$43*(1+Assumptions!$D$161)^5-DCF!$F$44*(1+Assumptions!$D$161)^5-DCF!$F$45*(1+Assumptions!$D$161)^5)/(1+DCF!$B$33)^DCF!$F$47+((DCF!$F$39*(1+Assumptions!$D$161)^5)*(DCF!$F$40/DCF!$F$39+Assumptions!$D$166)*(1-(-DCF!$F$41/DCF!$F$40))+DCF!$F$43*(1+Assumptions!$D$161)^5-DCF!$F$44*(1+Assumptions!$D$161)^5-DCF!$F$45*(1+Assumptions!$D$161)^5)*(1+DCF!$F$53)/(DCF!$B$33-DCF!$F$53)/(1+DCF!$B$33)^DCF!$F$47)-DCF!$B$62+DCF!$B$63-DCF!$B$64)/DCF!$B$66/DCF!$B$68 -> 28.782109 | C15: =((((DCF!$B$39*(1+Assumptions!$D$161)^1)*(DCF!$B$40/DCF!$B$39+Assumptions!$D$167)*(1-(-DCF!$B$41/DCF!$B$40))+DCF!$B$43*(1+Assumptions!$D$161)^1-DCF!$B$44*(1+Assumptions!$D$161)^1-DCF!$B$45*(1+Assumptions!$D$161)^1)/(1+DCF!$B$33)^DCF!$B$47+((DCF!$C$39*(1+Assumptions!$D$161)^2)*(DCF!$C$40/DCF!$C$39+Assumptions!$D$167)*(1-(-DCF!$C$41/DCF!$C$40))+DCF!$C$43*(1+Assumptions!$D$161)^2-DCF!$C$44*(1+Assumptions!$D$161)^2-DCF!$C$45*(1+Assumptions!$D$161)^2)/(1+DCF!$B$33)^DCF!$C$47+((DCF!$D$39*(1+Assumptions!$D$161)^3)*(DCF!$D$40/DCF!$D$39+Assumptions!$D$167)*(1-(-DCF!$D$41/DCF!$D$40))+DCF!$D$43*(1+Assumptions!$D$161)^3-DCF!$D$44*(1+Assumptions!$D$161)^3-DCF!$D$45*(1+Assumptions!$D$161)^3)/(1+DCF!$B$33)^DCF!$D$47+((DCF!$E$39*(1+Assumptions!$D$161)^4)*(DCF!$E$40/DCF!$E$39+Assumptions!$D$167)*(1-(-DCF!$E$41/DCF!$E$40))+DCF!$E$43*(1+Assumptions!$D$161)^4-DCF!$E$44*(1+Assumptions!$D$161)^4-DCF!$E$45*(1+Assumptions!$D$161)^4)/(1+DCF!$B$33)^DCF!$E$47+((DCF!$F$39*(1+Assumptions!$D$161)^5)*(DCF!$F$40/DCF!$F$39+Assumptions!$D$167)*(1-(-DCF!$F$41/DCF!$F$40))+DCF!$F$43*(1+Assumptions!$D$161)^5-DCF!$F$44*(1+Assumptions!$D$161)^5-DCF!$F$45*(1+Assumptions!$D$161)^5)/(1+DCF!$B$33)^DCF!$F$47+((DCF!$F$39*(1+Assumptions!$D$161)^5)*(DCF!$F$40/DCF!$F$39+Assumptions!$D$167)*(1-(-DCF!$F$41/DCF!$F$40))+DCF!$F$43*(1+Assumptions!$D$161)^5-DCF!$F$44*(1+Assumptions!$D$161)^5-DCF!$F$45*(1+Assumptions!$D$161)^5)*(1+DCF!$F$53)/(DCF!$B$33-DCF!$F$53)/(1+DCF!$B$33)^DCF!$F$47)-DCF!$B$62+DCF!$B$63-DCF!$B$64)/DCF!$B$66/DCF!$B$68 -> 34.022425 | D15: =((((DCF!$B$39*(1+Assumptions!$D$161)^1)*(DCF!$B$40/DCF!$B$39+Assumptions!$D$168)*(1-(-DCF!$B$41/DCF!$B$40))+DCF!$B$43*(1+Assumptions!$D$161)^1-DCF!$B$44*(1+Assumptions!$D$161)^1-DCF!$B$45*(1+Assumptions!$D$161)^1)/(1+DCF!$B$33)^DCF!$B$47+((DCF!$C$39*(1+Assumptions!$D$161)^2)*(DCF!$C$40/DCF!$C$39+Assumptions!$D$168)*(1-(-DCF!$C$41/DCF!$C$40))+DCF!$C$43*(1+Assumptions!$D$161)^2-DCF!$C$44*(1+Assumptions!$D$161)^2-DCF!$C$45*(1+Assumptions!$D$161)^2)/(1+DCF!$B$33)^DCF!$C$47+((DCF!$D$39*(1+Assumptions!$D$161)^3)*(DCF!$D$40/DCF!$D$39+Assumptions!$D$168)*(1-(-DCF!$D$41/DCF!$D$40))+DCF!$D$43*(1+Assumptions!$D$161)^3-DCF!$D$44*(1+Assumptions!$D$161)^3-DCF!$D$45*(1+Assumptions!$D$161)^3)/(1+DCF!$B$33)^DCF!$D$47+((DCF!$E$39*(1+Assumptions!$D$161)^4)*(DCF!$E$40/DCF!$E$39+Assumptions!$D$168)*(1-(-DCF!$E$41/DCF!$E$40))+DCF!$E$43*(1+Assumptions!$D$161)^4-DCF!$E$44*(1+Assumptions!$D$161)^4-DCF!$E$45*(1+Assumptions!$D$161)^4)/(1+DCF!$B$33)^DCF!$E$47+((DCF!$F$39*(1+Assumptions!$D$161)^5)*(DCF!$F$40/DCF!$F$39+Assumptions!$D$168)*(1-(-DCF!$F$41/DCF!$F$40))+DCF!$F$43*(1+Assumptions!$D$161)^5-DCF!$F$44*(1+Assumptions!$D$161)^5-DCF!$F$45*(1+Assumptions!$D$161)^5)/(1+DCF!$B$33)^DCF!$F$47+((DCF!$F$39*(1+Assumptions!$D$161)^5)*(DCF!$F$40/DCF!$F$39+Assumptions!$D$168)*(1-(-DCF!$F$41/DCF!$F$40))+DCF!$F$43*(1+Assumptions!$D$161)^5-DCF!$F$44*(1+Assumptions!$D$161)^5-DCF!$F$45*(1+Assumptions!$D$161)^5)*(1+DCF!$F$53)/(DCF!$B$33-DCF!$F$53)/(1+DCF!$B$33)^DCF!$F$47)-DCF!$B$62+DCF!$B$63-DCF!$B$64)/DCF!$B$66/DCF!$B$68 -> 39.262741 | E15: =((((DCF!$B$39*(1+Assumptions!$D$161)^1)*(DCF!$B$40/DCF!$B$39+Assumptions!$D$169)*(1-(-DCF!$B$41/DCF!$B$40))+DCF!$B$43*(1+Assumptions!$D$161)^1-DCF!$B$44*(1+Assumptions!$D$161)^1-DCF!$B$45*(1+Assumptions!$D$161)^1)/(1+DCF!$B$33)^DCF!$B$47+((DCF!$C$39*(1+Assumptions!$D$161)^2)*(DCF!$C$40/DCF!$C$39+Assumptions!$D$169)*(1-(-DCF!$C$41/DCF!$C$40))+DCF!$C$43*(1+Assumptions!$D$161)^2-DCF!$C$44*(1+Assumptions!$D$161)^2-DCF!$C$45*(1+Assumptions!$D$161)^2)/(1+DCF!$B$33)^DCF!$C$47+((DCF!$D$39*(1+Assumptions!$D$161)^3)*(DCF!$D$40/DCF!$D$39+Assumptions!$D$169)*(1-(-DCF!$D$41/DCF!$D$40))+DCF!$D$43*(1+Assumptions!$D$161)^3-DCF!$D$44*(1+Assumptions!$D$161)^3-DCF!$D$45*(1+Assumptions!$D$161)^3)/(1+DCF!$B$33)^DCF!$D$47+((DCF!$E$39*(1+Assumptions!$D$161)^4)*(DCF!$E$40/DCF!$E$39+Assumptions!$D$169)*(1-(-DCF!$E$41/DCF!$E$40))+DCF!$E$43*(1+Assumptions!$D$161)^4-DCF!$E$44*(1+Assumptions!$D$161)^4-DCF!$E$45*(1+Assumptions!$D$161)^4)/(1+DCF!$B$33)^DCF!$E$47+((DCF!$F$39*(1+Assumptions!$D$161)^5)*(DCF!$F$40/DCF!$F$39+Assumptions!$D$169)*(1-(-DCF!$F$41/DCF!$F$40))+DCF!$F$43*(1+Assumptions!$D$161)^5-DCF!$F$44*(1+Assumptions!$D$161)^5-DCF!$F$45*(1+Assumptions!$D$161)^5)/(1+DCF!$B$33)^DCF!$F$47+((DCF!$F$39*(1+Assumptions!$D$161)^5)*(DCF!$F$40/DCF!$F$39+Assumptions!$D$169)*(1-(-DCF!$F$41/DCF!$F$40))+DCF!$F$43*(1+Assumptions!$D$161)^5-DCF!$F$44*(1+Assumptions!$D$161)^5-DCF!$F$45*(1+Assumptions!$D$161)^5)*(1+DCF!$F$53)/(DCF!$B$33-DCF!$F$53)/(1+DCF!$B$33)^DCF!$F$47)-DCF!$B$62+DCF!$B$63-DCF!$B$64)/DCF!$B$66/DCF!$B$68 -> 44.503057 | F15: =((((DCF!$B$39*(1+Assumptions!$D$161)^1)*(DCF!$B$40/DCF!$B$39+Assumptions!$D$170)*(1-(-DCF!$B$41/DCF!$B$40))+DCF!$B$43*(1+Assumptions!$D$161)^1-DCF!$B$44*(1+Assumptions!$D$161)^1-DCF!$B$45*(1+Assumptions!$D$161)^1)/(1+DCF!$B$33)^DCF!$B$47+((DCF!$C$39*(1+Assumptions!$D$161)^2)*(DCF!$C$40/DCF!$C$39+Assumptions!$D$170)*(1-(-DCF!$C$41/DCF!$C$40))+DCF!$C$43*(1+Assumptions!$D$161)^2-DCF!$C$44*(1+Assumptions!$D$161)^2-DCF!$C$45*(1+Assumptions!$D$161)^2)/(1+DCF!$B$33)^DCF!$C$47+((DCF!$D$39*(1+Assumptions!$D$161)^3)*(DCF!$D$40/DCF!$D$39+Assumptions!$D$170)*(1-(-DCF!$D$41/DCF!$D$40))+DCF!$D$43*(1+Assumptions!$D$161)^3-DCF!$D$44*(1+Assumptions!$D$161)^3-DCF!$D$45*(1+Assumptions!$D$161)^3)/(1+DCF!$B$33)^DCF!$D$47+((DCF!$E$39*(1+Assumptions!$D$161)^4)*(DCF!$E$40/DCF!$E$39+Assumptions!$D$170)*(1-(-DCF!$E$41/DCF!$E$40))+DCF!$E$43*(1+Assumptions!$D$161)^4-DCF!$E$44*(1+Assumptions!$D$161)^4-DCF!$E$45*(1+Assumptions!$D$161)^4)/(1+DCF!$B$33)^DCF!$E$47+((DCF!$F$39*(1+Assumptions!$D$161)^5)*(DCF!$F$40/DCF!$F$39+Assumptions!$D$170)*(1-(-DCF!$F$41/DCF!$F$40))+DCF!$F$43*(1+Assumptions!$D$161)^5-DCF!$F$44*(1+Assumptions!$D$161)^5-DCF!$F$45*(1+Assumptions!$D$161)^5)/(1+DCF!$B$33)^DCF!$F$47+((DCF!$F$39*(1+Assumptions!$D$161)^5)*(DCF!$F$40/DCF!$F$39+Assumptions!$D$170)*(1-(-DCF!$F$41/DCF!$F$40))+DCF!$F$43*(1+Assumptions!$D$161)^5-DCF!$F$44*(1+Assumptions!$D$161)^5-DCF!$F$45*(1+Assumptions!$D$161)^5)*(1+DCF!$F$53)/(DCF!$B$33-DCF!$F$53)/(1+DCF!$B$33)^DCF!$F$47)-DCF!$B$62+DCF!$B$63-DCF!$B$64)/DCF!$B$66/DCF!$B$68 -> 49.743373
